## try...catch

### 开发中难免会碰到报错,可能是编写出错,也可能是服务端响应错误;通常如果发生错误 JS 就会终止执行;而 try...catch 能够帮助我们捕获异常,而不终止程序执行

- 语法
  ```
      try{
          ...
      }catch(err){
          ...
      }finally{
          ...
      }
  ```
  - 它由`try`和`catch`组成
    - 首先执行`try`中的代码
    - 如果没有错误则忽略`catch`中的代码,继续执行后面的后面的代码
    - 如果出现错误则终止执行,控制流转向`catch`
    - 不管是否出现错误都将执行`finally`中的代码
    - `try`后面必须有`catch`或`finally`,或两个都有

#### 它只能处理运行时的 error;如果 try 内有语法错误,try...catch 将会失效,并终止 JS 执行;JS 引擎会先读取代码,读取阶段发生的错误被称为'解析时间'错误,它会终止脚本执行,这是因为引擎无法理解该代码;所以 try...catch 只能处理'运行时错误',也被称为'异常'

#### 它无法捕捉到异步函数内的错误,如果要捕捉异步函数内的错误则需要将 try...catch 放在异步函数内部

#### 如果不需要 catch 的 error 参数也可以省略它

    ```
        try{...}catch{...}
    ```

#### catch 内还可以抛出错误,并且能够被外面的 catch 捕获到,如果外面没有 catch 的会就会终止代码执行

#### 如果使用 let 或 const 声明变量,则无法在 catch 和 finally 中使用改变量

#### 如果在 try 中进行了 return 操作,则当前 try...catch 代码块后的代码会终止执行,但是 finally 中的代码还是会继续执行;同样,如果 try 中出现了错误,并没有被 catch 捕获,则代码会终止执行,但 finally 中的代码也会被执行;
